[2024-06-07 14:07:36,824] {taskinstance.py:1032} INFO - Dependencies all met for <TaskInstance: data_ingestion_gcs_dag.transform_dataset_task manual__2024-06-07T14:07:32.533207+00:00 [queued]>
[2024-06-07 14:07:36,833] {taskinstance.py:1032} INFO - Dependencies all met for <TaskInstance: data_ingestion_gcs_dag.transform_dataset_task manual__2024-06-07T14:07:32.533207+00:00 [queued]>
[2024-06-07 14:07:36,833] {taskinstance.py:1238} INFO - 
--------------------------------------------------------------------------------
[2024-06-07 14:07:36,833] {taskinstance.py:1239} INFO - Starting attempt 1 of 2
[2024-06-07 14:07:36,833] {taskinstance.py:1240} INFO - 
--------------------------------------------------------------------------------
[2024-06-07 14:07:36,845] {taskinstance.py:1259} INFO - Executing <Task(PythonOperator): transform_dataset_task> on 2024-06-07 14:07:32.533207+00:00
[2024-06-07 14:07:36,851] {standard_task_runner.py:52} INFO - Started process 3184 to run task
[2024-06-07 14:07:36,854] {standard_task_runner.py:76} INFO - Running: ['***', 'tasks', 'run', 'data_ingestion_gcs_dag', 'transform_dataset_task', 'manual__2024-06-07T14:07:32.533207+00:00', '--job-id', '282', '--raw', '--subdir', 'DAGS_FOLDER/data_ingestion.py', '--cfg-path', '/tmp/tmpnvjhqv_4', '--error-file', '/tmp/tmpxlk1qio0']
[2024-06-07 14:07:36,858] {standard_task_runner.py:77} INFO - Job 282: Subtask transform_dataset_task
[2024-06-07 14:07:36,907] {logging_mixin.py:109} INFO - Running <TaskInstance: data_ingestion_gcs_dag.transform_dataset_task manual__2024-06-07T14:07:32.533207+00:00 [running]> on host fbb305b57b58
[2024-06-07 14:07:36,956] {taskinstance.py:1426} INFO - Exporting the following env vars:
AIRFLOW_CTX_DAG_OWNER=***
AIRFLOW_CTX_DAG_ID=data_ingestion_gcs_dag
AIRFLOW_CTX_TASK_ID=transform_dataset_task
AIRFLOW_CTX_EXECUTION_DATE=2024-06-07T14:07:32.533207+00:00
AIRFLOW_CTX_DAG_RUN_ID=manual__2024-06-07T14:07:32.533207+00:00
[2024-06-07 14:07:36,963] {logging_mixin.py:109} WARNING - /home/***/.local/lib/python3.6/site-packages/***/utils/context.py:152 AirflowContextDeprecationWarning: Accessing 'execution_date' from the template is deprecated and will be removed in a future version. Please use 'data_interval_start' or 'logical_date' instead.
[2024-06-07 14:07:36,964] {logging_mixin.py:109} WARNING - /home/***/.local/lib/python3.6/site-packages/***/utils/context.py:152 AirflowContextDeprecationWarning: Accessing 'next_ds' from the template is deprecated and will be removed in a future version. Please use '{{ data_interval_end | ds }}' instead.
[2024-06-07 14:07:36,965] {logging_mixin.py:109} WARNING - /home/***/.local/lib/python3.6/site-packages/***/utils/context.py:152 AirflowContextDeprecationWarning: Accessing 'next_ds_nodash' from the template is deprecated and will be removed in a future version. Please use '{{ data_interval_end | ds_nodash }}' instead.
[2024-06-07 14:07:36,966] {logging_mixin.py:109} WARNING - /home/***/.local/lib/python3.6/site-packages/***/utils/context.py:152 AirflowContextDeprecationWarning: Accessing 'next_execution_date' from the template is deprecated and will be removed in a future version. Please use 'data_interval_end' instead.
[2024-06-07 14:07:36,966] {logging_mixin.py:109} WARNING - /home/***/.local/lib/python3.6/site-packages/***/utils/context.py:152 AirflowContextDeprecationWarning: Accessing 'prev_ds' from the template is deprecated and will be removed in a future version.
[2024-06-07 14:07:36,967] {logging_mixin.py:109} WARNING - /home/***/.local/lib/python3.6/site-packages/***/utils/context.py:152 AirflowContextDeprecationWarning: Accessing 'prev_ds_nodash' from the template is deprecated and will be removed in a future version.
[2024-06-07 14:07:36,968] {logging_mixin.py:109} WARNING - /home/***/.local/lib/python3.6/site-packages/***/utils/context.py:152 AirflowContextDeprecationWarning: Accessing 'prev_execution_date' from the template is deprecated and will be removed in a future version.
[2024-06-07 14:07:36,969] {logging_mixin.py:109} WARNING - /home/***/.local/lib/python3.6/site-packages/***/utils/context.py:152 AirflowContextDeprecationWarning: Accessing 'prev_execution_date_success' from the template is deprecated and will be removed in a future version. Please use 'prev_data_interval_start_success' instead.
[2024-06-07 14:07:36,970] {logging_mixin.py:109} WARNING - /home/***/.local/lib/python3.6/site-packages/***/utils/context.py:152 AirflowContextDeprecationWarning: Accessing 'tomorrow_ds' from the template is deprecated and will be removed in a future version.
[2024-06-07 14:07:36,970] {logging_mixin.py:109} WARNING - /home/***/.local/lib/python3.6/site-packages/***/utils/context.py:152 AirflowContextDeprecationWarning: Accessing 'tomorrow_ds_nodash' from the template is deprecated and will be removed in a future version.
[2024-06-07 14:07:36,971] {logging_mixin.py:109} WARNING - /home/***/.local/lib/python3.6/site-packages/***/utils/context.py:152 AirflowContextDeprecationWarning: Accessing 'yesterday_ds' from the template is deprecated and will be removed in a future version.
[2024-06-07 14:07:36,972] {logging_mixin.py:109} WARNING - /home/***/.local/lib/python3.6/site-packages/***/utils/context.py:152 AirflowContextDeprecationWarning: Accessing 'yesterday_ds_nodash' from the template is deprecated and will be removed in a future version.
[2024-06-07 14:07:36,981] {taskinstance.py:1700} ERROR - Task failed with exception
Traceback (most recent call last):
  File "/home/airflow/.local/lib/python3.6/site-packages/airflow/models/taskinstance.py", line 1329, in _run_raw_task
    self._execute_task_with_callbacks(context)
  File "/home/airflow/.local/lib/python3.6/site-packages/airflow/models/taskinstance.py", line 1455, in _execute_task_with_callbacks
    result = self._execute_task(context, self.task)
  File "/home/airflow/.local/lib/python3.6/site-packages/airflow/models/taskinstance.py", line 1511, in _execute_task
    result = execute_callable(context=context)
  File "/home/airflow/.local/lib/python3.6/site-packages/airflow/operators/python.py", line 174, in execute
    return_value = self.execute_callable()
  File "/home/airflow/.local/lib/python3.6/site-packages/airflow/operators/python.py", line 185, in execute_callable
    return self.python_callable(*self.op_args, **self.op_kwargs)
  File "/opt/airflow/dags/data_ingestion.py", line 33, in transform_dataset
    task_ids="download_dataset_task"
AttributeError: __enter__
[2024-06-07 14:07:36,992] {taskinstance.py:1277} INFO - Marking task as UP_FOR_RETRY. dag_id=data_ingestion_gcs_dag, task_id=transform_dataset_task, execution_date=20240607T140732, start_date=20240607T140736, end_date=20240607T140736
[2024-06-07 14:07:37,005] {standard_task_runner.py:92} ERROR - Failed to execute job 282 for task transform_dataset_task
Traceback (most recent call last):
  File "/home/airflow/.local/lib/python3.6/site-packages/airflow/task/task_runner/standard_task_runner.py", line 85, in _start_by_fork
    args.func(args, dag=self.dag)
  File "/home/airflow/.local/lib/python3.6/site-packages/airflow/cli/cli_parser.py", line 48, in command
    return func(*args, **kwargs)
  File "/home/airflow/.local/lib/python3.6/site-packages/airflow/utils/cli.py", line 92, in wrapper
    return f(*args, **kwargs)
  File "/home/airflow/.local/lib/python3.6/site-packages/airflow/cli/commands/task_command.py", line 298, in task_run
    _run_task_by_selected_method(args, dag, ti)
  File "/home/airflow/.local/lib/python3.6/site-packages/airflow/cli/commands/task_command.py", line 107, in _run_task_by_selected_method
    _run_raw_task(args, ti)
  File "/home/airflow/.local/lib/python3.6/site-packages/airflow/cli/commands/task_command.py", line 184, in _run_raw_task
    error_file=args.error_file,
  File "/home/airflow/.local/lib/python3.6/site-packages/airflow/utils/session.py", line 70, in wrapper
    return func(*args, session=session, **kwargs)
  File "/home/airflow/.local/lib/python3.6/site-packages/airflow/models/taskinstance.py", line 1329, in _run_raw_task
    self._execute_task_with_callbacks(context)
  File "/home/airflow/.local/lib/python3.6/site-packages/airflow/models/taskinstance.py", line 1455, in _execute_task_with_callbacks
    result = self._execute_task(context, self.task)
  File "/home/airflow/.local/lib/python3.6/site-packages/airflow/models/taskinstance.py", line 1511, in _execute_task
    result = execute_callable(context=context)
  File "/home/airflow/.local/lib/python3.6/site-packages/airflow/operators/python.py", line 174, in execute
    return_value = self.execute_callable()
  File "/home/airflow/.local/lib/python3.6/site-packages/airflow/operators/python.py", line 185, in execute_callable
    return self.python_callable(*self.op_args, **self.op_kwargs)
  File "/opt/airflow/dags/data_ingestion.py", line 33, in transform_dataset
    task_ids="download_dataset_task"
AttributeError: __enter__
[2024-06-07 14:07:37,030] {local_task_job.py:154} INFO - Task exited with return code 1
[2024-06-07 14:07:37,066] {local_task_job.py:264} INFO - 0 downstream tasks scheduled from follow-on schedule check
