[2024-06-07 15:30:07,203] {taskinstance.py:1032} INFO - Dependencies all met for <TaskInstance: data_ingestion_gcs_dag.load_data_to_bq_task manual__2024-06-07T15:24:57.385655+00:00 [queued]>
[2024-06-07 15:30:07,213] {taskinstance.py:1032} INFO - Dependencies all met for <TaskInstance: data_ingestion_gcs_dag.load_data_to_bq_task manual__2024-06-07T15:24:57.385655+00:00 [queued]>
[2024-06-07 15:30:07,213] {taskinstance.py:1238} INFO - 
--------------------------------------------------------------------------------
[2024-06-07 15:30:07,214] {taskinstance.py:1239} INFO - Starting attempt 2 of 2
[2024-06-07 15:30:07,214] {taskinstance.py:1240} INFO - 
--------------------------------------------------------------------------------
[2024-06-07 15:30:07,229] {taskinstance.py:1259} INFO - Executing <Task(PythonOperator): load_data_to_bq_task> on 2024-06-07 15:24:57.385655+00:00
[2024-06-07 15:30:07,235] {standard_task_runner.py:52} INFO - Started process 10609 to run task
[2024-06-07 15:30:07,239] {standard_task_runner.py:76} INFO - Running: ['***', 'tasks', 'run', 'data_ingestion_gcs_dag', 'load_data_to_bq_task', 'manual__2024-06-07T15:24:57.385655+00:00', '--job-id', '333', '--raw', '--subdir', 'DAGS_FOLDER/data_ingestion.py', '--cfg-path', '/tmp/tmptsl61gn5', '--error-file', '/tmp/tmp5d747mx_']
[2024-06-07 15:30:07,243] {standard_task_runner.py:77} INFO - Job 333: Subtask load_data_to_bq_task
[2024-06-07 15:30:07,316] {logging_mixin.py:109} INFO - Running <TaskInstance: data_ingestion_gcs_dag.load_data_to_bq_task manual__2024-06-07T15:24:57.385655+00:00 [running]> on host fbb305b57b58
[2024-06-07 15:30:07,370] {taskinstance.py:1426} INFO - Exporting the following env vars:
AIRFLOW_CTX_DAG_OWNER=***
AIRFLOW_CTX_DAG_ID=data_ingestion_gcs_dag
AIRFLOW_CTX_TASK_ID=load_data_to_bq_task
AIRFLOW_CTX_EXECUTION_DATE=2024-06-07T15:24:57.385655+00:00
AIRFLOW_CTX_DAG_RUN_ID=manual__2024-06-07T15:24:57.385655+00:00
[2024-06-07 15:30:07,918] {taskinstance.py:1700} ERROR - Task failed with exception
Traceback (most recent call last):
  File "/home/airflow/.local/lib/python3.6/site-packages/airflow/models/taskinstance.py", line 1329, in _run_raw_task
    self._execute_task_with_callbacks(context)
  File "/home/airflow/.local/lib/python3.6/site-packages/airflow/models/taskinstance.py", line 1455, in _execute_task_with_callbacks
    result = self._execute_task(context, self.task)
  File "/home/airflow/.local/lib/python3.6/site-packages/airflow/models/taskinstance.py", line 1511, in _execute_task
    result = execute_callable(context=context)
  File "/home/airflow/.local/lib/python3.6/site-packages/airflow/operators/python.py", line 174, in execute
    return_value = self.execute_callable()
  File "/home/airflow/.local/lib/python3.6/site-packages/airflow/operators/python.py", line 185, in execute_callable
    return self.python_callable(*self.op_args, **self.op_kwargs)
  File "/opt/airflow/dags/load_to_bigquery.py", line 21, in load_data_to_bq
    load_job.result()
  File "/home/airflow/.local/lib/python3.6/site-packages/google/cloud/bigquery/job/base.py", line 727, in result
    return super(_AsyncJob, self).result(timeout=timeout, **kwargs)
  File "/home/airflow/.local/lib/python3.6/site-packages/google/api_core/future/polling.py", line 135, in result
    raise self._exception
google.api_core.exceptions.NotFound: 404 Not found: URI gs://nyt_most_viewved_bucket/new_york_times_most_viewed_2024-06-07_15-24-59.json
[2024-06-07 15:30:07,932] {taskinstance.py:1277} INFO - Marking task as FAILED. dag_id=data_ingestion_gcs_dag, task_id=load_data_to_bq_task, execution_date=20240607T152457, start_date=20240607T153007, end_date=20240607T153007
[2024-06-07 15:30:07,945] {standard_task_runner.py:92} ERROR - Failed to execute job 333 for task load_data_to_bq_task
Traceback (most recent call last):
  File "/home/airflow/.local/lib/python3.6/site-packages/airflow/task/task_runner/standard_task_runner.py", line 85, in _start_by_fork
    args.func(args, dag=self.dag)
  File "/home/airflow/.local/lib/python3.6/site-packages/airflow/cli/cli_parser.py", line 48, in command
    return func(*args, **kwargs)
  File "/home/airflow/.local/lib/python3.6/site-packages/airflow/utils/cli.py", line 92, in wrapper
    return f(*args, **kwargs)
  File "/home/airflow/.local/lib/python3.6/site-packages/airflow/cli/commands/task_command.py", line 298, in task_run
    _run_task_by_selected_method(args, dag, ti)
  File "/home/airflow/.local/lib/python3.6/site-packages/airflow/cli/commands/task_command.py", line 107, in _run_task_by_selected_method
    _run_raw_task(args, ti)
  File "/home/airflow/.local/lib/python3.6/site-packages/airflow/cli/commands/task_command.py", line 184, in _run_raw_task
    error_file=args.error_file,
  File "/home/airflow/.local/lib/python3.6/site-packages/airflow/utils/session.py", line 70, in wrapper
    return func(*args, session=session, **kwargs)
  File "/home/airflow/.local/lib/python3.6/site-packages/airflow/models/taskinstance.py", line 1329, in _run_raw_task
    self._execute_task_with_callbacks(context)
  File "/home/airflow/.local/lib/python3.6/site-packages/airflow/models/taskinstance.py", line 1455, in _execute_task_with_callbacks
    result = self._execute_task(context, self.task)
  File "/home/airflow/.local/lib/python3.6/site-packages/airflow/models/taskinstance.py", line 1511, in _execute_task
    result = execute_callable(context=context)
  File "/home/airflow/.local/lib/python3.6/site-packages/airflow/operators/python.py", line 174, in execute
    return_value = self.execute_callable()
  File "/home/airflow/.local/lib/python3.6/site-packages/airflow/operators/python.py", line 185, in execute_callable
    return self.python_callable(*self.op_args, **self.op_kwargs)
  File "/opt/airflow/dags/load_to_bigquery.py", line 21, in load_data_to_bq
    load_job.result()
  File "/home/airflow/.local/lib/python3.6/site-packages/google/cloud/bigquery/job/base.py", line 727, in result
    return super(_AsyncJob, self).result(timeout=timeout, **kwargs)
  File "/home/airflow/.local/lib/python3.6/site-packages/google/api_core/future/polling.py", line 135, in result
    raise self._exception
google.api_core.exceptions.NotFound: 404 Not found: URI gs://nyt_most_viewved_bucket/new_york_times_most_viewed_2024-06-07_15-24-59.json
[2024-06-07 15:30:07,978] {local_task_job.py:154} INFO - Task exited with return code 1
[2024-06-07 15:30:08,009] {local_task_job.py:264} INFO - 0 downstream tasks scheduled from follow-on schedule check
