[2024-06-07 14:29:45,565] {taskinstance.py:1032} INFO - Dependencies all met for <TaskInstance: data_ingestion_gcs_dag.upload_to_gcs_task manual__2024-06-07T14:29:38.397362+00:00 [queued]>
[2024-06-07 14:29:45,576] {taskinstance.py:1032} INFO - Dependencies all met for <TaskInstance: data_ingestion_gcs_dag.upload_to_gcs_task manual__2024-06-07T14:29:38.397362+00:00 [queued]>
[2024-06-07 14:29:45,576] {taskinstance.py:1238} INFO - 
--------------------------------------------------------------------------------
[2024-06-07 14:29:45,576] {taskinstance.py:1239} INFO - Starting attempt 1 of 2
[2024-06-07 14:29:45,576] {taskinstance.py:1240} INFO - 
--------------------------------------------------------------------------------
[2024-06-07 14:29:45,589] {taskinstance.py:1259} INFO - Executing <Task(PythonOperator): upload_to_gcs_task> on 2024-06-07 14:29:38.397362+00:00
[2024-06-07 14:29:45,594] {standard_task_runner.py:52} INFO - Started process 5150 to run task
[2024-06-07 14:29:45,597] {standard_task_runner.py:76} INFO - Running: ['***', 'tasks', 'run', 'data_ingestion_gcs_dag', 'upload_to_gcs_task', 'manual__2024-06-07T14:29:38.397362+00:00', '--job-id', '290', '--raw', '--subdir', 'DAGS_FOLDER/data_ingestion.py', '--cfg-path', '/tmp/tmpr1pz91io', '--error-file', '/tmp/tmp63a2fuft']
[2024-06-07 14:29:45,600] {standard_task_runner.py:77} INFO - Job 290: Subtask upload_to_gcs_task
[2024-06-07 14:29:45,657] {logging_mixin.py:109} INFO - Running <TaskInstance: data_ingestion_gcs_dag.upload_to_gcs_task manual__2024-06-07T14:29:38.397362+00:00 [running]> on host fbb305b57b58
[2024-06-07 14:29:45,715] {taskinstance.py:1426} INFO - Exporting the following env vars:
AIRFLOW_CTX_DAG_OWNER=***
AIRFLOW_CTX_DAG_ID=data_ingestion_gcs_dag
AIRFLOW_CTX_TASK_ID=upload_to_gcs_task
AIRFLOW_CTX_EXECUTION_DATE=2024-06-07T14:29:38.397362+00:00
AIRFLOW_CTX_DAG_RUN_ID=manual__2024-06-07T14:29:38.397362+00:00
[2024-06-07 14:29:45,915] {taskinstance.py:1700} ERROR - Task failed with exception
Traceback (most recent call last):
  File "/home/airflow/.local/lib/python3.6/site-packages/google/cloud/storage/blob.py", line 2594, in upload_from_file
    retry=retry,
  File "/home/airflow/.local/lib/python3.6/site-packages/google/cloud/storage/blob.py", line 2396, in _do_upload
    retry=retry,
  File "/home/airflow/.local/lib/python3.6/site-packages/google/cloud/storage/blob.py", line 1917, in _do_multipart_upload
    transport, data, object_metadata, content_type, timeout=timeout
  File "/home/airflow/.local/lib/python3.6/site-packages/google/resumable_media/requests/upload.py", line 154, in transmit
    retriable_request, self._get_status_code, self._retry_strategy
  File "/home/airflow/.local/lib/python3.6/site-packages/google/resumable_media/requests/_request_helpers.py", line 147, in wait_and_retry
    response = func()
  File "/home/airflow/.local/lib/python3.6/site-packages/google/resumable_media/requests/upload.py", line 149, in retriable_request
    self._process_response(result)
  File "/home/airflow/.local/lib/python3.6/site-packages/google/resumable_media/_upload.py", line 113, in _process_response
    _helpers.require_status_code(response, (http.client.OK,), self._get_status_code)
  File "/home/airflow/.local/lib/python3.6/site-packages/google/resumable_media/_helpers.py", line 104, in require_status_code
    *status_codes
google.resumable_media.common.InvalidResponse: ('Request failed with status code', 412, 'Expected one of', <HTTPStatus.OK: 200>)

During handling of the above exception, another exception occurred:

Traceback (most recent call last):
  File "/home/airflow/.local/lib/python3.6/site-packages/airflow/models/taskinstance.py", line 1329, in _run_raw_task
    self._execute_task_with_callbacks(context)
  File "/home/airflow/.local/lib/python3.6/site-packages/airflow/models/taskinstance.py", line 1455, in _execute_task_with_callbacks
    result = self._execute_task(context, self.task)
  File "/home/airflow/.local/lib/python3.6/site-packages/airflow/models/taskinstance.py", line 1511, in _execute_task
    result = execute_callable(context=context)
  File "/home/airflow/.local/lib/python3.6/site-packages/airflow/operators/python.py", line 174, in execute
    return_value = self.execute_callable()
  File "/home/airflow/.local/lib/python3.6/site-packages/airflow/operators/python.py", line 185, in execute_callable
    return self.python_callable(*self.op_args, **self.op_kwargs)
  File "/opt/airflow/dags/data_ingestion.py", line 38, in upload_blob
    source_file_name, if_generation_match=generation_match_precondition
  File "/home/airflow/.local/lib/python3.6/site-packages/google/cloud/storage/blob.py", line 2735, in upload_from_filename
    retry=retry,
  File "/home/airflow/.local/lib/python3.6/site-packages/google/cloud/storage/blob.py", line 2598, in upload_from_file
    _raise_from_invalid_response(exc)
  File "/home/airflow/.local/lib/python3.6/site-packages/google/cloud/storage/blob.py", line 4466, in _raise_from_invalid_response
    raise exceptions.from_http_status(response.status_code, message, response=response)
google.api_core.exceptions.PreconditionFailed: 412 POST https://storage.googleapis.com/upload/storage/v1/b/nyt_most_viewved_bucket/o?uploadType=multipart&ifGenerationMatch=0: {
  "error": {
    "code": 412,
    "message": "At least one of the pre-conditions you specified did not hold.",
    "errors": [
      {
        "message": "At least one of the pre-conditions you specified did not hold.",
        "domain": "global",
        "reason": "conditionNotMet",
        "locationType": "header",
        "location": "If-Match"
      }
    ]
  }
}
: ('Request failed with status code', 412, 'Expected one of', <HTTPStatus.OK: 200>)
[2024-06-07 14:29:45,929] {taskinstance.py:1277} INFO - Marking task as UP_FOR_RETRY. dag_id=data_ingestion_gcs_dag, task_id=upload_to_gcs_task, execution_date=20240607T142938, start_date=20240607T142945, end_date=20240607T142945
[2024-06-07 14:29:45,941] {standard_task_runner.py:92} ERROR - Failed to execute job 290 for task upload_to_gcs_task
Traceback (most recent call last):
  File "/home/airflow/.local/lib/python3.6/site-packages/google/cloud/storage/blob.py", line 2594, in upload_from_file
    retry=retry,
  File "/home/airflow/.local/lib/python3.6/site-packages/google/cloud/storage/blob.py", line 2396, in _do_upload
    retry=retry,
  File "/home/airflow/.local/lib/python3.6/site-packages/google/cloud/storage/blob.py", line 1917, in _do_multipart_upload
    transport, data, object_metadata, content_type, timeout=timeout
  File "/home/airflow/.local/lib/python3.6/site-packages/google/resumable_media/requests/upload.py", line 154, in transmit
    retriable_request, self._get_status_code, self._retry_strategy
  File "/home/airflow/.local/lib/python3.6/site-packages/google/resumable_media/requests/_request_helpers.py", line 147, in wait_and_retry
    response = func()
  File "/home/airflow/.local/lib/python3.6/site-packages/google/resumable_media/requests/upload.py", line 149, in retriable_request
    self._process_response(result)
  File "/home/airflow/.local/lib/python3.6/site-packages/google/resumable_media/_upload.py", line 113, in _process_response
    _helpers.require_status_code(response, (http.client.OK,), self._get_status_code)
  File "/home/airflow/.local/lib/python3.6/site-packages/google/resumable_media/_helpers.py", line 104, in require_status_code
    *status_codes
google.resumable_media.common.InvalidResponse: ('Request failed with status code', 412, 'Expected one of', <HTTPStatus.OK: 200>)

During handling of the above exception, another exception occurred:

Traceback (most recent call last):
  File "/home/airflow/.local/lib/python3.6/site-packages/airflow/task/task_runner/standard_task_runner.py", line 85, in _start_by_fork
    args.func(args, dag=self.dag)
  File "/home/airflow/.local/lib/python3.6/site-packages/airflow/cli/cli_parser.py", line 48, in command
    return func(*args, **kwargs)
  File "/home/airflow/.local/lib/python3.6/site-packages/airflow/utils/cli.py", line 92, in wrapper
    return f(*args, **kwargs)
  File "/home/airflow/.local/lib/python3.6/site-packages/airflow/cli/commands/task_command.py", line 298, in task_run
    _run_task_by_selected_method(args, dag, ti)
  File "/home/airflow/.local/lib/python3.6/site-packages/airflow/cli/commands/task_command.py", line 107, in _run_task_by_selected_method
    _run_raw_task(args, ti)
  File "/home/airflow/.local/lib/python3.6/site-packages/airflow/cli/commands/task_command.py", line 184, in _run_raw_task
    error_file=args.error_file,
  File "/home/airflow/.local/lib/python3.6/site-packages/airflow/utils/session.py", line 70, in wrapper
    return func(*args, session=session, **kwargs)
  File "/home/airflow/.local/lib/python3.6/site-packages/airflow/models/taskinstance.py", line 1329, in _run_raw_task
    self._execute_task_with_callbacks(context)
  File "/home/airflow/.local/lib/python3.6/site-packages/airflow/models/taskinstance.py", line 1455, in _execute_task_with_callbacks
    result = self._execute_task(context, self.task)
  File "/home/airflow/.local/lib/python3.6/site-packages/airflow/models/taskinstance.py", line 1511, in _execute_task
    result = execute_callable(context=context)
  File "/home/airflow/.local/lib/python3.6/site-packages/airflow/operators/python.py", line 174, in execute
    return_value = self.execute_callable()
  File "/home/airflow/.local/lib/python3.6/site-packages/airflow/operators/python.py", line 185, in execute_callable
    return self.python_callable(*self.op_args, **self.op_kwargs)
  File "/opt/airflow/dags/data_ingestion.py", line 38, in upload_blob
    source_file_name, if_generation_match=generation_match_precondition
  File "/home/airflow/.local/lib/python3.6/site-packages/google/cloud/storage/blob.py", line 2735, in upload_from_filename
    retry=retry,
  File "/home/airflow/.local/lib/python3.6/site-packages/google/cloud/storage/blob.py", line 2598, in upload_from_file
    _raise_from_invalid_response(exc)
  File "/home/airflow/.local/lib/python3.6/site-packages/google/cloud/storage/blob.py", line 4466, in _raise_from_invalid_response
    raise exceptions.from_http_status(response.status_code, message, response=response)
google.api_core.exceptions.PreconditionFailed: 412 POST https://storage.googleapis.com/upload/storage/v1/b/nyt_most_viewved_bucket/o?uploadType=multipart&ifGenerationMatch=0: {
  "error": {
    "code": 412,
    "message": "At least one of the pre-conditions you specified did not hold.",
    "errors": [
      {
        "message": "At least one of the pre-conditions you specified did not hold.",
        "domain": "global",
        "reason": "conditionNotMet",
        "locationType": "header",
        "location": "If-Match"
      }
    ]
  }
}
: ('Request failed with status code', 412, 'Expected one of', <HTTPStatus.OK: 200>)
[2024-06-07 14:29:45,973] {local_task_job.py:154} INFO - Task exited with return code 1
[2024-06-07 14:29:46,007] {local_task_job.py:264} INFO - 0 downstream tasks scheduled from follow-on schedule check
