[2024-06-07 14:34:46,851] {taskinstance.py:1032} INFO - Dependencies all met for <TaskInstance: data_ingestion_gcs_dag.upload_to_gcs_task manual__2024-06-07T14:29:38.397362+00:00 [queued]>
[2024-06-07 14:34:46,861] {taskinstance.py:1032} INFO - Dependencies all met for <TaskInstance: data_ingestion_gcs_dag.upload_to_gcs_task manual__2024-06-07T14:29:38.397362+00:00 [queued]>
[2024-06-07 14:34:46,861] {taskinstance.py:1238} INFO - 
--------------------------------------------------------------------------------
[2024-06-07 14:34:46,862] {taskinstance.py:1239} INFO - Starting attempt 2 of 2
[2024-06-07 14:34:46,862] {taskinstance.py:1240} INFO - 
--------------------------------------------------------------------------------
[2024-06-07 14:34:46,875] {taskinstance.py:1259} INFO - Executing <Task(PythonOperator): upload_to_gcs_task> on 2024-06-07 14:29:38.397362+00:00
[2024-06-07 14:34:46,879] {standard_task_runner.py:52} INFO - Started process 5581 to run task
[2024-06-07 14:34:46,883] {standard_task_runner.py:76} INFO - Running: ['***', 'tasks', 'run', 'data_ingestion_gcs_dag', 'upload_to_gcs_task', 'manual__2024-06-07T14:29:38.397362+00:00', '--job-id', '291', '--raw', '--subdir', 'DAGS_FOLDER/data_ingestion.py', '--cfg-path', '/tmp/tmp0lij8j67', '--error-file', '/tmp/tmp_9fq73dn']
[2024-06-07 14:34:46,886] {standard_task_runner.py:77} INFO - Job 291: Subtask upload_to_gcs_task
[2024-06-07 14:34:46,934] {logging_mixin.py:109} INFO - Running <TaskInstance: data_ingestion_gcs_dag.upload_to_gcs_task manual__2024-06-07T14:29:38.397362+00:00 [running]> on host fbb305b57b58
[2024-06-07 14:34:47,009] {taskinstance.py:1426} INFO - Exporting the following env vars:
AIRFLOW_CTX_DAG_OWNER=***
AIRFLOW_CTX_DAG_ID=data_ingestion_gcs_dag
AIRFLOW_CTX_TASK_ID=upload_to_gcs_task
AIRFLOW_CTX_EXECUTION_DATE=2024-06-07T14:29:38.397362+00:00
AIRFLOW_CTX_DAG_RUN_ID=manual__2024-06-07T14:29:38.397362+00:00
[2024-06-07 14:34:47,023] {taskinstance.py:1700} ERROR - Task failed with exception
Traceback (most recent call last):
  File "/home/airflow/.local/lib/python3.6/site-packages/airflow/models/taskinstance.py", line 1329, in _run_raw_task
    self._execute_task_with_callbacks(context)
  File "/home/airflow/.local/lib/python3.6/site-packages/airflow/models/taskinstance.py", line 1455, in _execute_task_with_callbacks
    result = self._execute_task(context, self.task)
  File "/home/airflow/.local/lib/python3.6/site-packages/airflow/models/taskinstance.py", line 1511, in _execute_task
    result = execute_callable(context=context)
  File "/home/airflow/.local/lib/python3.6/site-packages/airflow/operators/python.py", line 174, in execute
    return_value = self.execute_callable()
  File "/home/airflow/.local/lib/python3.6/site-packages/airflow/operators/python.py", line 185, in execute_callable
    return self.python_callable(*self.op_args, **self.op_kwargs)
  File "/opt/airflow/dags/data_ingestion.py", line 38, in upload_blob
    source_file_name, if_generation_match=generation_match_precondition
  File "/home/airflow/.local/lib/python3.6/site-packages/google/cloud/storage/blob.py", line 2720, in upload_from_filename
    with open(filename, "rb") as file_obj:
FileNotFoundError: [Errno 2] No such file or directory: '/opt/airflow/transformed_data.json'
[2024-06-07 14:34:47,038] {taskinstance.py:1277} INFO - Marking task as FAILED. dag_id=data_ingestion_gcs_dag, task_id=upload_to_gcs_task, execution_date=20240607T142938, start_date=20240607T143446, end_date=20240607T143447
[2024-06-07 14:34:47,050] {standard_task_runner.py:92} ERROR - Failed to execute job 291 for task upload_to_gcs_task
Traceback (most recent call last):
  File "/home/airflow/.local/lib/python3.6/site-packages/airflow/task/task_runner/standard_task_runner.py", line 85, in _start_by_fork
    args.func(args, dag=self.dag)
  File "/home/airflow/.local/lib/python3.6/site-packages/airflow/cli/cli_parser.py", line 48, in command
    return func(*args, **kwargs)
  File "/home/airflow/.local/lib/python3.6/site-packages/airflow/utils/cli.py", line 92, in wrapper
    return f(*args, **kwargs)
  File "/home/airflow/.local/lib/python3.6/site-packages/airflow/cli/commands/task_command.py", line 298, in task_run
    _run_task_by_selected_method(args, dag, ti)
  File "/home/airflow/.local/lib/python3.6/site-packages/airflow/cli/commands/task_command.py", line 107, in _run_task_by_selected_method
    _run_raw_task(args, ti)
  File "/home/airflow/.local/lib/python3.6/site-packages/airflow/cli/commands/task_command.py", line 184, in _run_raw_task
    error_file=args.error_file,
  File "/home/airflow/.local/lib/python3.6/site-packages/airflow/utils/session.py", line 70, in wrapper
    return func(*args, session=session, **kwargs)
  File "/home/airflow/.local/lib/python3.6/site-packages/airflow/models/taskinstance.py", line 1329, in _run_raw_task
    self._execute_task_with_callbacks(context)
  File "/home/airflow/.local/lib/python3.6/site-packages/airflow/models/taskinstance.py", line 1455, in _execute_task_with_callbacks
    result = self._execute_task(context, self.task)
  File "/home/airflow/.local/lib/python3.6/site-packages/airflow/models/taskinstance.py", line 1511, in _execute_task
    result = execute_callable(context=context)
  File "/home/airflow/.local/lib/python3.6/site-packages/airflow/operators/python.py", line 174, in execute
    return_value = self.execute_callable()
  File "/home/airflow/.local/lib/python3.6/site-packages/airflow/operators/python.py", line 185, in execute_callable
    return self.python_callable(*self.op_args, **self.op_kwargs)
  File "/opt/airflow/dags/data_ingestion.py", line 38, in upload_blob
    source_file_name, if_generation_match=generation_match_precondition
  File "/home/airflow/.local/lib/python3.6/site-packages/google/cloud/storage/blob.py", line 2720, in upload_from_filename
    with open(filename, "rb") as file_obj:
FileNotFoundError: [Errno 2] No such file or directory: '/opt/airflow/transformed_data.json'
[2024-06-07 14:34:47,058] {local_task_job.py:154} INFO - Task exited with return code 1
[2024-06-07 14:34:47,114] {local_task_job.py:264} INFO - 0 downstream tasks scheduled from follow-on schedule check
